2021-10-16 14:07:56,206:DEBUG:Using selector: EpollSelector
2021-10-16 14:08:03,319:DEBUG:Using selector: EpollSelector
2021-10-16 14:08:10,058:DEBUG:Using selector: EpollSelector
2021-10-16 14:08:18,887:DEBUG:Using selector: EpollSelector
2021-10-16 14:09:20,199:DEBUG:Starting new HTTPS connection (1): www.google.com:443
2021-10-16 14:09:20,704:DEBUG:https://www.google.com:443 "GET /recaptcha/api/siteverify?secret=Your+Code+here&response=&remoteip=127.0.0.1 HTTP/1.1" 200 None
2021-10-16 14:09:20,855:DEBUG:


----------------


برای فعال سازی اکانت خود روی لینک زیر کلیک کنید
94.183.230.36:8000/active/?username=test&code=GCpNTlgjEBBlF9y7wx7i8maM5S3T


----------------



2021-10-16 15:30:11,053:INFO:/home/ramed/w/nextodo/web/models.py changed, reloading.
2021-10-16 15:30:11,054:DEBUG:Using selector: EpollSelector
2021-10-16 15:30:19,154:DEBUG:Using selector: EpollSelector
2021-10-16 15:30:26,055:DEBUG:Using selector: EpollSelector
2021-10-16 15:37:30,773:ERROR:Internal Server Error: /
Traceback (most recent call last):
  File "/home/ramed/w/nextodo/.venv/lib/python3.9/site-packages/django/db/backends/utils.py", line 84, in _execute
    return self.cursor.execute(sql, params)
  File "/home/ramed/w/nextodo/.venv/lib/python3.9/site-packages/django/db/backends/sqlite3/base.py", line 423, in execute
    return Database.Cursor.execute(self, query, params)
sqlite3.OperationalError: no such table: web_news

The above exception was the direct cause of the following exception:

Traceback (most recent call last):
  File "/home/ramed/w/nextodo/.venv/lib/python3.9/site-packages/django/core/handlers/exception.py", line 47, in inner
    response = get_response(request)
  File "/home/ramed/w/nextodo/.venv/lib/python3.9/site-packages/django/core/handlers/base.py", line 181, in _get_response
    response = wrapped_callback(request, *callback_args, **callback_kwargs)
  File "/home/ramed/w/nextodo/web/views.py", line 66, in index_view
    return render(request, 'index.html', context)
  File "/home/ramed/w/nextodo/.venv/lib/python3.9/site-packages/django/shortcuts.py", line 19, in render
    content = loader.render_to_string(template_name, context, request, using=using)
  File "/home/ramed/w/nextodo/.venv/lib/python3.9/site-packages/django/template/loader.py", line 62, in render_to_string
    return template.render(context, request)
  File "/home/ramed/w/nextodo/.venv/lib/python3.9/site-packages/django/template/backends/django.py", line 61, in render
    return self.template.render(context)
  File "/home/ramed/w/nextodo/.venv/lib/python3.9/site-packages/django/template/base.py", line 170, in render
    return self._render(context)
  File "/home/ramed/w/nextodo/.venv/lib/python3.9/site-packages/django/template/base.py", line 162, in _render
    return self.nodelist.render(context)
  File "/home/ramed/w/nextodo/.venv/lib/python3.9/site-packages/django/template/base.py", line 938, in render
    bit = node.render_annotated(context)
  File "/home/ramed/w/nextodo/.venv/lib/python3.9/site-packages/django/template/base.py", line 905, in render_annotated
    return self.render(context)
  File "/home/ramed/w/nextodo/.venv/lib/python3.9/site-packages/django/template/defaulttags.py", line 168, in render
    len_values = len(values)
  File "/home/ramed/w/nextodo/.venv/lib/python3.9/site-packages/django/db/models/query.py", line 262, in __len__
    self._fetch_all()
  File "/home/ramed/w/nextodo/.venv/lib/python3.9/site-packages/django/db/models/query.py", line 1324, in _fetch_all
    self._result_cache = list(self._iterable_class(self))
  File "/home/ramed/w/nextodo/.venv/lib/python3.9/site-packages/django/db/models/query.py", line 51, in __iter__
    results = compiler.execute_sql(chunked_fetch=self.chunked_fetch, chunk_size=self.chunk_size)
  File "/home/ramed/w/nextodo/.venv/lib/python3.9/site-packages/django/db/models/sql/compiler.py", line 1175, in execute_sql
    cursor.execute(sql, params)
  File "/home/ramed/w/nextodo/.venv/lib/python3.9/site-packages/django/db/backends/utils.py", line 98, in execute
    return super().execute(sql, params)
  File "/home/ramed/w/nextodo/.venv/lib/python3.9/site-packages/django/db/backends/utils.py", line 66, in execute
    return self._execute_with_wrappers(sql, params, many=False, executor=self._execute)
  File "/home/ramed/w/nextodo/.venv/lib/python3.9/site-packages/django/db/backends/utils.py", line 75, in _execute_with_wrappers
    return executor(sql, params, many, context)
  File "/home/ramed/w/nextodo/.venv/lib/python3.9/site-packages/django/db/backends/utils.py", line 84, in _execute
    return self.cursor.execute(sql, params)
  File "/home/ramed/w/nextodo/.venv/lib/python3.9/site-packages/django/db/utils.py", line 90, in __exit__
    raise dj_exc_value.with_traceback(traceback) from exc_value
  File "/home/ramed/w/nextodo/.venv/lib/python3.9/site-packages/django/db/backends/utils.py", line 84, in _execute
    return self.cursor.execute(sql, params)
  File "/home/ramed/w/nextodo/.venv/lib/python3.9/site-packages/django/db/backends/sqlite3/base.py", line 423, in execute
    return Database.Cursor.execute(self, query, params)
django.db.utils.OperationalError: no such table: web_news
2021-10-16 15:37:30,964:WARNING:Not Found: /favicon.ico
2021-10-16 15:38:03,675:DEBUG:Using selector: EpollSelector
2021-10-16 15:38:07,160:ERROR:Internal Server Error: /
Traceback (most recent call last):
  File "/home/ramed/w/nextodo/.venv/lib/python3.9/site-packages/django/db/backends/utils.py", line 84, in _execute
    return self.cursor.execute(sql, params)
  File "/home/ramed/w/nextodo/.venv/lib/python3.9/site-packages/django/db/backends/sqlite3/base.py", line 423, in execute
    return Database.Cursor.execute(self, query, params)
sqlite3.OperationalError: no such table: web_news

The above exception was the direct cause of the following exception:

Traceback (most recent call last):
  File "/home/ramed/w/nextodo/.venv/lib/python3.9/site-packages/django/core/handlers/exception.py", line 47, in inner
    response = get_response(request)
  File "/home/ramed/w/nextodo/.venv/lib/python3.9/site-packages/django/core/handlers/base.py", line 181, in _get_response
    response = wrapped_callback(request, *callback_args, **callback_kwargs)
  File "/home/ramed/w/nextodo/web/views.py", line 66, in index_view
    return render(request, 'index.html', context)
  File "/home/ramed/w/nextodo/.venv/lib/python3.9/site-packages/django/shortcuts.py", line 19, in render
    content = loader.render_to_string(template_name, context, request, using=using)
  File "/home/ramed/w/nextodo/.venv/lib/python3.9/site-packages/django/template/loader.py", line 62, in render_to_string
    return template.render(context, request)
  File "/home/ramed/w/nextodo/.venv/lib/python3.9/site-packages/django/template/backends/django.py", line 61, in render
    return self.template.render(context)
  File "/home/ramed/w/nextodo/.venv/lib/python3.9/site-packages/django/template/base.py", line 170, in render
    return self._render(context)
  File "/home/ramed/w/nextodo/.venv/lib/python3.9/site-packages/django/template/base.py", line 162, in _render
    return self.nodelist.render(context)
  File "/home/ramed/w/nextodo/.venv/lib/python3.9/site-packages/django/template/base.py", line 938, in render
    bit = node.render_annotated(context)
  File "/home/ramed/w/nextodo/.venv/lib/python3.9/site-packages/django/template/base.py", line 905, in render_annotated
    return self.render(context)
  File "/home/ramed/w/nextodo/.venv/lib/python3.9/site-packages/django/template/defaulttags.py", line 168, in render
    len_values = len(values)
  File "/home/ramed/w/nextodo/.venv/lib/python3.9/site-packages/django/db/models/query.py", line 262, in __len__
    self._fetch_all()
  File "/home/ramed/w/nextodo/.venv/lib/python3.9/site-packages/django/db/models/query.py", line 1324, in _fetch_all
    self._result_cache = list(self._iterable_class(self))
  File "/home/ramed/w/nextodo/.venv/lib/python3.9/site-packages/django/db/models/query.py", line 51, in __iter__
    results = compiler.execute_sql(chunked_fetch=self.chunked_fetch, chunk_size=self.chunk_size)
  File "/home/ramed/w/nextodo/.venv/lib/python3.9/site-packages/django/db/models/sql/compiler.py", line 1175, in execute_sql
    cursor.execute(sql, params)
  File "/home/ramed/w/nextodo/.venv/lib/python3.9/site-packages/django/db/backends/utils.py", line 98, in execute
    return super().execute(sql, params)
  File "/home/ramed/w/nextodo/.venv/lib/python3.9/site-packages/django/db/backends/utils.py", line 66, in execute
    return self._execute_with_wrappers(sql, params, many=False, executor=self._execute)
  File "/home/ramed/w/nextodo/.venv/lib/python3.9/site-packages/django/db/backends/utils.py", line 75, in _execute_with_wrappers
    return executor(sql, params, many, context)
  File "/home/ramed/w/nextodo/.venv/lib/python3.9/site-packages/django/db/backends/utils.py", line 84, in _execute
    return self.cursor.execute(sql, params)
  File "/home/ramed/w/nextodo/.venv/lib/python3.9/site-packages/django/db/utils.py", line 90, in __exit__
    raise dj_exc_value.with_traceback(traceback) from exc_value
  File "/home/ramed/w/nextodo/.venv/lib/python3.9/site-packages/django/db/backends/utils.py", line 84, in _execute
    return self.cursor.execute(sql, params)
  File "/home/ramed/w/nextodo/.venv/lib/python3.9/site-packages/django/db/backends/sqlite3/base.py", line 423, in execute
    return Database.Cursor.execute(self, query, params)
django.db.utils.OperationalError: no such table: web_news
2021-10-16 15:38:08,638:ERROR:Internal Server Error: /
Traceback (most recent call last):
  File "/home/ramed/w/nextodo/.venv/lib/python3.9/site-packages/django/db/backends/utils.py", line 84, in _execute
    return self.cursor.execute(sql, params)
  File "/home/ramed/w/nextodo/.venv/lib/python3.9/site-packages/django/db/backends/sqlite3/base.py", line 423, in execute
    return Database.Cursor.execute(self, query, params)
sqlite3.OperationalError: no such table: web_news

The above exception was the direct cause of the following exception:

Traceback (most recent call last):
  File "/home/ramed/w/nextodo/.venv/lib/python3.9/site-packages/django/core/handlers/exception.py", line 47, in inner
    response = get_response(request)
  File "/home/ramed/w/nextodo/.venv/lib/python3.9/site-packages/django/core/handlers/base.py", line 181, in _get_response
    response = wrapped_callback(request, *callback_args, **callback_kwargs)
  File "/home/ramed/w/nextodo/web/views.py", line 66, in index_view
    return render(request, 'index.html', context)
  File "/home/ramed/w/nextodo/.venv/lib/python3.9/site-packages/django/shortcuts.py", line 19, in render
    content = loader.render_to_string(template_name, context, request, using=using)
  File "/home/ramed/w/nextodo/.venv/lib/python3.9/site-packages/django/template/loader.py", line 62, in render_to_string
    return template.render(context, request)
  File "/home/ramed/w/nextodo/.venv/lib/python3.9/site-packages/django/template/backends/django.py", line 61, in render
    return self.template.render(context)
  File "/home/ramed/w/nextodo/.venv/lib/python3.9/site-packages/django/template/base.py", line 170, in render
    return self._render(context)
  File "/home/ramed/w/nextodo/.venv/lib/python3.9/site-packages/django/template/base.py", line 162, in _render
    return self.nodelist.render(context)
  File "/home/ramed/w/nextodo/.venv/lib/python3.9/site-packages/django/template/base.py", line 938, in render
    bit = node.render_annotated(context)
  File "/home/ramed/w/nextodo/.venv/lib/python3.9/site-packages/django/template/base.py", line 905, in render_annotated
    return self.render(context)
  File "/home/ramed/w/nextodo/.venv/lib/python3.9/site-packages/django/template/defaulttags.py", line 168, in render
    len_values = len(values)
  File "/home/ramed/w/nextodo/.venv/lib/python3.9/site-packages/django/db/models/query.py", line 262, in __len__
    self._fetch_all()
  File "/home/ramed/w/nextodo/.venv/lib/python3.9/site-packages/django/db/models/query.py", line 1324, in _fetch_all
    self._result_cache = list(self._iterable_class(self))
  File "/home/ramed/w/nextodo/.venv/lib/python3.9/site-packages/django/db/models/query.py", line 51, in __iter__
    results = compiler.execute_sql(chunked_fetch=self.chunked_fetch, chunk_size=self.chunk_size)
  File "/home/ramed/w/nextodo/.venv/lib/python3.9/site-packages/django/db/models/sql/compiler.py", line 1175, in execute_sql
    cursor.execute(sql, params)
  File "/home/ramed/w/nextodo/.venv/lib/python3.9/site-packages/django/db/backends/utils.py", line 98, in execute
    return super().execute(sql, params)
  File "/home/ramed/w/nextodo/.venv/lib/python3.9/site-packages/django/db/backends/utils.py", line 66, in execute
    return self._execute_with_wrappers(sql, params, many=False, executor=self._execute)
  File "/home/ramed/w/nextodo/.venv/lib/python3.9/site-packages/django/db/backends/utils.py", line 75, in _execute_with_wrappers
    return executor(sql, params, many, context)
  File "/home/ramed/w/nextodo/.venv/lib/python3.9/site-packages/django/db/backends/utils.py", line 84, in _execute
    return self.cursor.execute(sql, params)
  File "/home/ramed/w/nextodo/.venv/lib/python3.9/site-packages/django/db/utils.py", line 90, in __exit__
    raise dj_exc_value.with_traceback(traceback) from exc_value
  File "/home/ramed/w/nextodo/.venv/lib/python3.9/site-packages/django/db/backends/utils.py", line 84, in _execute
    return self.cursor.execute(sql, params)
  File "/home/ramed/w/nextodo/.venv/lib/python3.9/site-packages/django/db/backends/sqlite3/base.py", line 423, in execute
    return Database.Cursor.execute(self, query, params)
django.db.utils.OperationalError: no such table: web_news
2021-10-16 15:38:09,461:ERROR:Internal Server Error: /
Traceback (most recent call last):
  File "/home/ramed/w/nextodo/.venv/lib/python3.9/site-packages/django/db/backends/utils.py", line 84, in _execute
    return self.cursor.execute(sql, params)
  File "/home/ramed/w/nextodo/.venv/lib/python3.9/site-packages/django/db/backends/sqlite3/base.py", line 423, in execute
    return Database.Cursor.execute(self, query, params)
sqlite3.OperationalError: no such table: web_news

The above exception was the direct cause of the following exception:

Traceback (most recent call last):
  File "/home/ramed/w/nextodo/.venv/lib/python3.9/site-packages/django/core/handlers/exception.py", line 47, in inner
    response = get_response(request)
  File "/home/ramed/w/nextodo/.venv/lib/python3.9/site-packages/django/core/handlers/base.py", line 181, in _get_response
    response = wrapped_callback(request, *callback_args, **callback_kwargs)
  File "/home/ramed/w/nextodo/web/views.py", line 66, in index_view
    return render(request, 'index.html', context)
  File "/home/ramed/w/nextodo/.venv/lib/python3.9/site-packages/django/shortcuts.py", line 19, in render
    content = loader.render_to_string(template_name, context, request, using=using)
  File "/home/ramed/w/nextodo/.venv/lib/python3.9/site-packages/django/template/loader.py", line 62, in render_to_string
    return template.render(context, request)
  File "/home/ramed/w/nextodo/.venv/lib/python3.9/site-packages/django/template/backends/django.py", line 61, in render
    return self.template.render(context)
  File "/home/ramed/w/nextodo/.venv/lib/python3.9/site-packages/django/template/base.py", line 170, in render
    return self._render(context)
  File "/home/ramed/w/nextodo/.venv/lib/python3.9/site-packages/django/template/base.py", line 162, in _render
    return self.nodelist.render(context)
  File "/home/ramed/w/nextodo/.venv/lib/python3.9/site-packages/django/template/base.py", line 938, in render
    bit = node.render_annotated(context)
  File "/home/ramed/w/nextodo/.venv/lib/python3.9/site-packages/django/template/base.py", line 905, in render_annotated
    return self.render(context)
  File "/home/ramed/w/nextodo/.venv/lib/python3.9/site-packages/django/template/defaulttags.py", line 168, in render
    len_values = len(values)
  File "/home/ramed/w/nextodo/.venv/lib/python3.9/site-packages/django/db/models/query.py", line 262, in __len__
    self._fetch_all()
  File "/home/ramed/w/nextodo/.venv/lib/python3.9/site-packages/django/db/models/query.py", line 1324, in _fetch_all
    self._result_cache = list(self._iterable_class(self))
  File "/home/ramed/w/nextodo/.venv/lib/python3.9/site-packages/django/db/models/query.py", line 51, in __iter__
    results = compiler.execute_sql(chunked_fetch=self.chunked_fetch, chunk_size=self.chunk_size)
  File "/home/ramed/w/nextodo/.venv/lib/python3.9/site-packages/django/db/models/sql/compiler.py", line 1175, in execute_sql
    cursor.execute(sql, params)
  File "/home/ramed/w/nextodo/.venv/lib/python3.9/site-packages/django/db/backends/utils.py", line 98, in execute
    return super().execute(sql, params)
  File "/home/ramed/w/nextodo/.venv/lib/python3.9/site-packages/django/db/backends/utils.py", line 66, in execute
    return self._execute_with_wrappers(sql, params, many=False, executor=self._execute)
  File "/home/ramed/w/nextodo/.venv/lib/python3.9/site-packages/django/db/backends/utils.py", line 75, in _execute_with_wrappers
    return executor(sql, params, many, context)
  File "/home/ramed/w/nextodo/.venv/lib/python3.9/site-packages/django/db/backends/utils.py", line 84, in _execute
    return self.cursor.execute(sql, params)
  File "/home/ramed/w/nextodo/.venv/lib/python3.9/site-packages/django/db/utils.py", line 90, in __exit__
    raise dj_exc_value.with_traceback(traceback) from exc_value
  File "/home/ramed/w/nextodo/.venv/lib/python3.9/site-packages/django/db/backends/utils.py", line 84, in _execute
    return self.cursor.execute(sql, params)
  File "/home/ramed/w/nextodo/.venv/lib/python3.9/site-packages/django/db/backends/sqlite3/base.py", line 423, in execute
    return Database.Cursor.execute(self, query, params)
django.db.utils.OperationalError: no such table: web_news
2021-10-16 15:38:30,953:ERROR:Internal Server Error: /
Traceback (most recent call last):
  File "/home/ramed/w/nextodo/.venv/lib/python3.9/site-packages/django/db/backends/utils.py", line 84, in _execute
    return self.cursor.execute(sql, params)
  File "/home/ramed/w/nextodo/.venv/lib/python3.9/site-packages/django/db/backends/sqlite3/base.py", line 423, in execute
    return Database.Cursor.execute(self, query, params)
sqlite3.OperationalError: no such table: web_news

The above exception was the direct cause of the following exception:

Traceback (most recent call last):
  File "/home/ramed/w/nextodo/.venv/lib/python3.9/site-packages/django/core/handlers/exception.py", line 47, in inner
    response = get_response(request)
  File "/home/ramed/w/nextodo/.venv/lib/python3.9/site-packages/django/core/handlers/base.py", line 181, in _get_response
    response = wrapped_callback(request, *callback_args, **callback_kwargs)
  File "/home/ramed/w/nextodo/web/views.py", line 66, in index_view
    return render(request, 'index.html', context)
  File "/home/ramed/w/nextodo/.venv/lib/python3.9/site-packages/django/shortcuts.py", line 19, in render
    content = loader.render_to_string(template_name, context, request, using=using)
  File "/home/ramed/w/nextodo/.venv/lib/python3.9/site-packages/django/template/loader.py", line 62, in render_to_string
    return template.render(context, request)
  File "/home/ramed/w/nextodo/.venv/lib/python3.9/site-packages/django/template/backends/django.py", line 61, in render
    return self.template.render(context)
  File "/home/ramed/w/nextodo/.venv/lib/python3.9/site-packages/django/template/base.py", line 170, in render
    return self._render(context)
  File "/home/ramed/w/nextodo/.venv/lib/python3.9/site-packages/django/template/base.py", line 162, in _render
    return self.nodelist.render(context)
  File "/home/ramed/w/nextodo/.venv/lib/python3.9/site-packages/django/template/base.py", line 938, in render
    bit = node.render_annotated(context)
  File "/home/ramed/w/nextodo/.venv/lib/python3.9/site-packages/django/template/base.py", line 905, in render_annotated
    return self.render(context)
  File "/home/ramed/w/nextodo/.venv/lib/python3.9/site-packages/django/template/defaulttags.py", line 168, in render
    len_values = len(values)
  File "/home/ramed/w/nextodo/.venv/lib/python3.9/site-packages/django/db/models/query.py", line 262, in __len__
    self._fetch_all()
  File "/home/ramed/w/nextodo/.venv/lib/python3.9/site-packages/django/db/models/query.py", line 1324, in _fetch_all
    self._result_cache = list(self._iterable_class(self))
  File "/home/ramed/w/nextodo/.venv/lib/python3.9/site-packages/django/db/models/query.py", line 51, in __iter__
    results = compiler.execute_sql(chunked_fetch=self.chunked_fetch, chunk_size=self.chunk_size)
  File "/home/ramed/w/nextodo/.venv/lib/python3.9/site-packages/django/db/models/sql/compiler.py", line 1175, in execute_sql
    cursor.execute(sql, params)
  File "/home/ramed/w/nextodo/.venv/lib/python3.9/site-packages/django/db/backends/utils.py", line 98, in execute
    return super().execute(sql, params)
  File "/home/ramed/w/nextodo/.venv/lib/python3.9/site-packages/django/db/backends/utils.py", line 66, in execute
    return self._execute_with_wrappers(sql, params, many=False, executor=self._execute)
  File "/home/ramed/w/nextodo/.venv/lib/python3.9/site-packages/django/db/backends/utils.py", line 75, in _execute_with_wrappers
    return executor(sql, params, many, context)
  File "/home/ramed/w/nextodo/.venv/lib/python3.9/site-packages/django/db/backends/utils.py", line 84, in _execute
    return self.cursor.execute(sql, params)
  File "/home/ramed/w/nextodo/.venv/lib/python3.9/site-packages/django/db/utils.py", line 90, in __exit__
    raise dj_exc_value.with_traceback(traceback) from exc_value
  File "/home/ramed/w/nextodo/.venv/lib/python3.9/site-packages/django/db/backends/utils.py", line 84, in _execute
    return self.cursor.execute(sql, params)
  File "/home/ramed/w/nextodo/.venv/lib/python3.9/site-packages/django/db/backends/sqlite3/base.py", line 423, in execute
    return Database.Cursor.execute(self, query, params)
django.db.utils.OperationalError: no such table: web_news
2021-10-16 15:40:02,261:INFO:/home/ramed/w/nextodo/web/views.py changed, reloading.
2021-10-16 15:40:02,262:DEBUG:Using selector: EpollSelector
2021-10-16 15:40:23,398:ERROR:Internal Server Error: /
Traceback (most recent call last):
  File "/home/ramed/w/nextodo/.venv/lib/python3.9/site-packages/django/db/backends/utils.py", line 84, in _execute
    return self.cursor.execute(sql, params)
  File "/home/ramed/w/nextodo/.venv/lib/python3.9/site-packages/django/db/backends/sqlite3/base.py", line 423, in execute
    return Database.Cursor.execute(self, query, params)
sqlite3.OperationalError: no such table: web_news

The above exception was the direct cause of the following exception:

Traceback (most recent call last):
  File "/home/ramed/w/nextodo/.venv/lib/python3.9/site-packages/django/core/handlers/exception.py", line 47, in inner
    response = get_response(request)
  File "/home/ramed/w/nextodo/.venv/lib/python3.9/site-packages/django/core/handlers/base.py", line 181, in _get_response
    response = wrapped_callback(request, *callback_args, **callback_kwargs)
  File "/home/ramed/w/nextodo/web/views.py", line 61, in index_view
    if news.objects.filter(is_active=True).exists():
  File "/home/ramed/w/nextodo/.venv/lib/python3.9/site-packages/django/db/models/query.py", line 808, in exists
    return self.query.has_results(using=self.db)
  File "/home/ramed/w/nextodo/.venv/lib/python3.9/site-packages/django/db/models/sql/query.py", line 552, in has_results
    return compiler.has_results()
  File "/home/ramed/w/nextodo/.venv/lib/python3.9/site-packages/django/db/models/sql/compiler.py", line 1145, in has_results
    return bool(self.execute_sql(SINGLE))
  File "/home/ramed/w/nextodo/.venv/lib/python3.9/site-packages/django/db/models/sql/compiler.py", line 1175, in execute_sql
    cursor.execute(sql, params)
  File "/home/ramed/w/nextodo/.venv/lib/python3.9/site-packages/django/db/backends/utils.py", line 98, in execute
    return super().execute(sql, params)
  File "/home/ramed/w/nextodo/.venv/lib/python3.9/site-packages/django/db/backends/utils.py", line 66, in execute
    return self._execute_with_wrappers(sql, params, many=False, executor=self._execute)
  File "/home/ramed/w/nextodo/.venv/lib/python3.9/site-packages/django/db/backends/utils.py", line 75, in _execute_with_wrappers
    return executor(sql, params, many, context)
  File "/home/ramed/w/nextodo/.venv/lib/python3.9/site-packages/django/db/backends/utils.py", line 84, in _execute
    return self.cursor.execute(sql, params)
  File "/home/ramed/w/nextodo/.venv/lib/python3.9/site-packages/django/db/utils.py", line 90, in __exit__
    raise dj_exc_value.with_traceback(traceback) from exc_value
  File "/home/ramed/w/nextodo/.venv/lib/python3.9/site-packages/django/db/backends/utils.py", line 84, in _execute
    return self.cursor.execute(sql, params)
  File "/home/ramed/w/nextodo/.venv/lib/python3.9/site-packages/django/db/backends/sqlite3/base.py", line 423, in execute
    return Database.Cursor.execute(self, query, params)
django.db.utils.OperationalError: no such table: web_news
2021-10-16 15:40:24,737:ERROR:Internal Server Error: /
Traceback (most recent call last):
  File "/home/ramed/w/nextodo/.venv/lib/python3.9/site-packages/django/db/backends/utils.py", line 84, in _execute
    return self.cursor.execute(sql, params)
  File "/home/ramed/w/nextodo/.venv/lib/python3.9/site-packages/django/db/backends/sqlite3/base.py", line 423, in execute
    return Database.Cursor.execute(self, query, params)
sqlite3.OperationalError: no such table: web_news

The above exception was the direct cause of the following exception:

Traceback (most recent call last):
  File "/home/ramed/w/nextodo/.venv/lib/python3.9/site-packages/django/core/handlers/exception.py", line 47, in inner
    response = get_response(request)
  File "/home/ramed/w/nextodo/.venv/lib/python3.9/site-packages/django/core/handlers/base.py", line 181, in _get_response
    response = wrapped_callback(request, *callback_args, **callback_kwargs)
  File "/home/ramed/w/nextodo/web/views.py", line 61, in index_view
    if news.objects.filter(is_active=True).exists():
  File "/home/ramed/w/nextodo/.venv/lib/python3.9/site-packages/django/db/models/query.py", line 808, in exists
    return self.query.has_results(using=self.db)
  File "/home/ramed/w/nextodo/.venv/lib/python3.9/site-packages/django/db/models/sql/query.py", line 552, in has_results
    return compiler.has_results()
  File "/home/ramed/w/nextodo/.venv/lib/python3.9/site-packages/django/db/models/sql/compiler.py", line 1145, in has_results
    return bool(self.execute_sql(SINGLE))
  File "/home/ramed/w/nextodo/.venv/lib/python3.9/site-packages/django/db/models/sql/compiler.py", line 1175, in execute_sql
    cursor.execute(sql, params)
  File "/home/ramed/w/nextodo/.venv/lib/python3.9/site-packages/django/db/backends/utils.py", line 98, in execute
    return super().execute(sql, params)
  File "/home/ramed/w/nextodo/.venv/lib/python3.9/site-packages/django/db/backends/utils.py", line 66, in execute
    return self._execute_with_wrappers(sql, params, many=False, executor=self._execute)
  File "/home/ramed/w/nextodo/.venv/lib/python3.9/site-packages/django/db/backends/utils.py", line 75, in _execute_with_wrappers
    return executor(sql, params, many, context)
  File "/home/ramed/w/nextodo/.venv/lib/python3.9/site-packages/django/db/backends/utils.py", line 84, in _execute
    return self.cursor.execute(sql, params)
  File "/home/ramed/w/nextodo/.venv/lib/python3.9/site-packages/django/db/utils.py", line 90, in __exit__
    raise dj_exc_value.with_traceback(traceback) from exc_value
  File "/home/ramed/w/nextodo/.venv/lib/python3.9/site-packages/django/db/backends/utils.py", line 84, in _execute
    return self.cursor.execute(sql, params)
  File "/home/ramed/w/nextodo/.venv/lib/python3.9/site-packages/django/db/backends/sqlite3/base.py", line 423, in execute
    return Database.Cursor.execute(self, query, params)
django.db.utils.OperationalError: no such table: web_news
2021-10-16 15:40:25,430:ERROR:Internal Server Error: /
Traceback (most recent call last):
  File "/home/ramed/w/nextodo/.venv/lib/python3.9/site-packages/django/db/backends/utils.py", line 84, in _execute
    return self.cursor.execute(sql, params)
  File "/home/ramed/w/nextodo/.venv/lib/python3.9/site-packages/django/db/backends/sqlite3/base.py", line 423, in execute
    return Database.Cursor.execute(self, query, params)
sqlite3.OperationalError: no such table: web_news

The above exception was the direct cause of the following exception:

Traceback (most recent call last):
  File "/home/ramed/w/nextodo/.venv/lib/python3.9/site-packages/django/core/handlers/exception.py", line 47, in inner
    response = get_response(request)
  File "/home/ramed/w/nextodo/.venv/lib/python3.9/site-packages/django/core/handlers/base.py", line 181, in _get_response
    response = wrapped_callback(request, *callback_args, **callback_kwargs)
  File "/home/ramed/w/nextodo/web/views.py", line 61, in index_view
    if news.objects.filter(is_active=True).exists():
  File "/home/ramed/w/nextodo/.venv/lib/python3.9/site-packages/django/db/models/query.py", line 808, in exists
    return self.query.has_results(using=self.db)
  File "/home/ramed/w/nextodo/.venv/lib/python3.9/site-packages/django/db/models/sql/query.py", line 552, in has_results
    return compiler.has_results()
  File "/home/ramed/w/nextodo/.venv/lib/python3.9/site-packages/django/db/models/sql/compiler.py", line 1145, in has_results
    return bool(self.execute_sql(SINGLE))
  File "/home/ramed/w/nextodo/.venv/lib/python3.9/site-packages/django/db/models/sql/compiler.py", line 1175, in execute_sql
    cursor.execute(sql, params)
  File "/home/ramed/w/nextodo/.venv/lib/python3.9/site-packages/django/db/backends/utils.py", line 98, in execute
    return super().execute(sql, params)
  File "/home/ramed/w/nextodo/.venv/lib/python3.9/site-packages/django/db/backends/utils.py", line 66, in execute
    return self._execute_with_wrappers(sql, params, many=False, executor=self._execute)
  File "/home/ramed/w/nextodo/.venv/lib/python3.9/site-packages/django/db/backends/utils.py", line 75, in _execute_with_wrappers
    return executor(sql, params, many, context)
  File "/home/ramed/w/nextodo/.venv/lib/python3.9/site-packages/django/db/backends/utils.py", line 84, in _execute
    return self.cursor.execute(sql, params)
  File "/home/ramed/w/nextodo/.venv/lib/python3.9/site-packages/django/db/utils.py", line 90, in __exit__
    raise dj_exc_value.with_traceback(traceback) from exc_value
  File "/home/ramed/w/nextodo/.venv/lib/python3.9/site-packages/django/db/backends/utils.py", line 84, in _execute
    return self.cursor.execute(sql, params)
  File "/home/ramed/w/nextodo/.venv/lib/python3.9/site-packages/django/db/backends/sqlite3/base.py", line 423, in execute
    return Database.Cursor.execute(self, query, params)
django.db.utils.OperationalError: no such table: web_news
2021-10-16 15:40:26,202:ERROR:Internal Server Error: /
Traceback (most recent call last):
  File "/home/ramed/w/nextodo/.venv/lib/python3.9/site-packages/django/db/backends/utils.py", line 84, in _execute
    return self.cursor.execute(sql, params)
  File "/home/ramed/w/nextodo/.venv/lib/python3.9/site-packages/django/db/backends/sqlite3/base.py", line 423, in execute
    return Database.Cursor.execute(self, query, params)
sqlite3.OperationalError: no such table: web_news

The above exception was the direct cause of the following exception:

Traceback (most recent call last):
  File "/home/ramed/w/nextodo/.venv/lib/python3.9/site-packages/django/core/handlers/exception.py", line 47, in inner
    response = get_response(request)
  File "/home/ramed/w/nextodo/.venv/lib/python3.9/site-packages/django/core/handlers/base.py", line 181, in _get_response
    response = wrapped_callback(request, *callback_args, **callback_kwargs)
  File "/home/ramed/w/nextodo/web/views.py", line 61, in index_view
    if news.objects.filter(is_active=True).exists():
  File "/home/ramed/w/nextodo/.venv/lib/python3.9/site-packages/django/db/models/query.py", line 808, in exists
    return self.query.has_results(using=self.db)
  File "/home/ramed/w/nextodo/.venv/lib/python3.9/site-packages/django/db/models/sql/query.py", line 552, in has_results
    return compiler.has_results()
  File "/home/ramed/w/nextodo/.venv/lib/python3.9/site-packages/django/db/models/sql/compiler.py", line 1145, in has_results
    return bool(self.execute_sql(SINGLE))
  File "/home/ramed/w/nextodo/.venv/lib/python3.9/site-packages/django/db/models/sql/compiler.py", line 1175, in execute_sql
    cursor.execute(sql, params)
  File "/home/ramed/w/nextodo/.venv/lib/python3.9/site-packages/django/db/backends/utils.py", line 98, in execute
    return super().execute(sql, params)
  File "/home/ramed/w/nextodo/.venv/lib/python3.9/site-packages/django/db/backends/utils.py", line 66, in execute
    return self._execute_with_wrappers(sql, params, many=False, executor=self._execute)
  File "/home/ramed/w/nextodo/.venv/lib/python3.9/site-packages/django/db/backends/utils.py", line 75, in _execute_with_wrappers
    return executor(sql, params, many, context)
  File "/home/ramed/w/nextodo/.venv/lib/python3.9/site-packages/django/db/backends/utils.py", line 84, in _execute
    return self.cursor.execute(sql, params)
  File "/home/ramed/w/nextodo/.venv/lib/python3.9/site-packages/django/db/utils.py", line 90, in __exit__
    raise dj_exc_value.with_traceback(traceback) from exc_value
  File "/home/ramed/w/nextodo/.venv/lib/python3.9/site-packages/django/db/backends/utils.py", line 84, in _execute
    return self.cursor.execute(sql, params)
  File "/home/ramed/w/nextodo/.venv/lib/python3.9/site-packages/django/db/backends/sqlite3/base.py", line 423, in execute
    return Database.Cursor.execute(self, query, params)
django.db.utils.OperationalError: no such table: web_news
2021-10-16 15:40:26,591:ERROR:Internal Server Error: /
Traceback (most recent call last):
  File "/home/ramed/w/nextodo/.venv/lib/python3.9/site-packages/django/db/backends/utils.py", line 84, in _execute
    return self.cursor.execute(sql, params)
  File "/home/ramed/w/nextodo/.venv/lib/python3.9/site-packages/django/db/backends/sqlite3/base.py", line 423, in execute
    return Database.Cursor.execute(self, query, params)
sqlite3.OperationalError: no such table: web_news

The above exception was the direct cause of the following exception:

Traceback (most recent call last):
  File "/home/ramed/w/nextodo/.venv/lib/python3.9/site-packages/django/core/handlers/exception.py", line 47, in inner
    response = get_response(request)
  File "/home/ramed/w/nextodo/.venv/lib/python3.9/site-packages/django/core/handlers/base.py", line 181, in _get_response
    response = wrapped_callback(request, *callback_args, **callback_kwargs)
  File "/home/ramed/w/nextodo/web/views.py", line 61, in index_view
    if news.objects.filter(is_active=True).exists():
  File "/home/ramed/w/nextodo/.venv/lib/python3.9/site-packages/django/db/models/query.py", line 808, in exists
    return self.query.has_results(using=self.db)
  File "/home/ramed/w/nextodo/.venv/lib/python3.9/site-packages/django/db/models/sql/query.py", line 552, in has_results
    return compiler.has_results()
  File "/home/ramed/w/nextodo/.venv/lib/python3.9/site-packages/django/db/models/sql/compiler.py", line 1145, in has_results
    return bool(self.execute_sql(SINGLE))
  File "/home/ramed/w/nextodo/.venv/lib/python3.9/site-packages/django/db/models/sql/compiler.py", line 1175, in execute_sql
    cursor.execute(sql, params)
  File "/home/ramed/w/nextodo/.venv/lib/python3.9/site-packages/django/db/backends/utils.py", line 98, in execute
    return super().execute(sql, params)
  File "/home/ramed/w/nextodo/.venv/lib/python3.9/site-packages/django/db/backends/utils.py", line 66, in execute
    return self._execute_with_wrappers(sql, params, many=False, executor=self._execute)
  File "/home/ramed/w/nextodo/.venv/lib/python3.9/site-packages/django/db/backends/utils.py", line 75, in _execute_with_wrappers
    return executor(sql, params, many, context)
  File "/home/ramed/w/nextodo/.venv/lib/python3.9/site-packages/django/db/backends/utils.py", line 84, in _execute
    return self.cursor.execute(sql, params)
  File "/home/ramed/w/nextodo/.venv/lib/python3.9/site-packages/django/db/utils.py", line 90, in __exit__
    raise dj_exc_value.with_traceback(traceback) from exc_value
  File "/home/ramed/w/nextodo/.venv/lib/python3.9/site-packages/django/db/backends/utils.py", line 84, in _execute
    return self.cursor.execute(sql, params)
  File "/home/ramed/w/nextodo/.venv/lib/python3.9/site-packages/django/db/backends/sqlite3/base.py", line 423, in execute
    return Database.Cursor.execute(self, query, params)
django.db.utils.OperationalError: no such table: web_news
2021-10-16 15:40:43,657:DEBUG:Using selector: EpollSelector
2021-10-16 15:40:46,532:DEBUG:Using selector: EpollSelector
2021-10-16 15:40:50,820:DEBUG:Using selector: EpollSelector
